Training model...
Traceback (most recent call last):
  File "c:\Users\Erick\Desktop\Project\Jupyter\DlhJupyterNotebook\train.py", line 53, in <module>
    trainer.train_model()
    ~~~~~~~~~~~~~~~~~~~^^
  File "c:\Users\Erick\Desktop\Project\Jupyter\DlhJupyterNotebook\train.py", line 27, in train_model
    wandb.save("logistic_model.pkl")
    ~~~~~~~~~~^^^^^^^^^^^^^^^^^^^^^^
  File "C:\Users\Erick\miniconda3\Lib\site-packages\wandb\sdk\wandb_run.py", line 406, in wrapper
    return func(self, *args, **kwargs)
  File "C:\Users\Erick\miniconda3\Lib\site-packages\wandb\sdk\wandb_run.py", line 464, in wrapper_fn
    return func(self, *args, **kwargs)
  File "C:\Users\Erick\miniconda3\Lib\site-packages\wandb\sdk\wandb_run.py", line 451, in wrapper
    return func(self, *args, **kwargs)
  File "C:\Users\Erick\miniconda3\Lib\site-packages\wandb\sdk\wandb_run.py", line 2175, in save
    return self._save(
           ~~~~~~~~~~^
        resolved_glob_path,
        ^^^^^^^^^^^^^^^^^^^
        resolved_base_path,
        ^^^^^^^^^^^^^^^^^^^
        policy,
        ^^^^^^^
    )
    ^
  File "C:\Users\Erick\miniconda3\Lib\site-packages\wandb\sdk\wandb_run.py", line 2234, in _save
    target_path.symlink_to(source_path)
    ~~~~~~~~~~~~~~~~~~~~~~^^^^^^^^^^^^^
  File "C:\Users\Erick\miniconda3\Lib\pathlib\_local.py", line 789, in symlink_to
    os.symlink(target, self, target_is_directory)
    ~~~~~~~~~~^^^^^^^^^^^^^^^^^^^^^^^^^^^^^^^^^^^
OSError: [WinError 1314] A required privilege is not held by the client: 'C:\\Users\\Erick\\Desktop\\Project\\Jupyter\\DlhJupyterNotebook\\logistic_model.pkl' -> 'C:\\Users\\Erick\\Desktop\\Project\\Jupyter\\DlhJupyterNotebook\\wandb\\run-20250528_173155-j07r6ylj\\files\\logistic_model.pkl'
