Error executing job with overrides: []
joblib.externals.loky.process_executor._RemoteTraceback:
"""
Traceback (most recent call last):
  File "c:\Users\Erick\Desktop\Project\Jupyter\DlhJupyterNotebook\train.py", line 35, in train_model
    model.train(X_train, y_train)
    ~~~~~~~~~~~^^^^^^^^^^^^^^^^^^
  File "c:\Users\Erick\Desktop\Project\Jupyter\DlhJupyterNotebook\model.py", line 8, in train
    self.model.fit(X_train, y_train)
    ~~~~~~~~~~~~~~^^^^^^^^^^^^^^^^^^
  File "C:\Users\Erick\miniconda3\Lib\site-packages\sklearn\base.py", line 1382, in wrapper
    estimator._validate_params()
    ~~~~~~~~~~~~~~~~~~~~~~~~~~^^
  File "C:\Users\Erick\miniconda3\Lib\site-packages\sklearn\base.py", line 436, in _validate_params
    validate_parameter_constraints(
    ~~~~~~~~~~~~~~~~~~~~~~~~~~~~~~^
        self._parameter_constraints,
        ^^^^^^^^^^^^^^^^^^^^^^^^^^^^
        self.get_params(deep=False),
        ^^^^^^^^^^^^^^^^^^^^^^^^^^^^
        caller_name=self.__class__.__name__,
        ^^^^^^^^^^^^^^^^^^^^^^^^^^^^^^^^^^^^
    )
    ^
  File "C:\Users\Erick\miniconda3\Lib\site-packages\sklearn\utils\_param_validation.py", line 98, in validate_parameter_constraints
    raise InvalidParameterError(
    ...<2 lines>...
    )
sklearn.utils._param_validation.InvalidParameterError: The 'n_neighbors' parameter of KNeighborsClassifier must be an int in the range [1, inf) or None. Got [3, 5, 7] instead.

During handling of the above exception, another exception occurred:

Traceback (most recent call last):
  File "C:\Users\Erick\miniconda3\Lib\site-packages\joblib\externals\loky\process_executor.py", line 463, in _process_worker
    r = call_item()
  File "C:\Users\Erick\miniconda3\Lib\site-packages\joblib\externals\loky\process_executor.py", line 291, in __call__
    return self.fn(*self.args, **self.kwargs)
           ~~~~~~~^^^^^^^^^^^^^^^^^^^^^^^^^^^
  File "C:\Users\Erick\miniconda3\Lib\site-packages\joblib\parallel.py", line 598, in __call__
    return [func(*args, **kwargs)
            ~~~~^^^^^^^^^^^^^^^^^
  File "c:\Users\Erick\Desktop\Project\Jupyter\DlhJupyterNotebook\train.py", line 76, in train_model
    wandb.log({f"{name} Training Error": str(e)})
    ~~~~~~~~~^^^^^^^^^^^^^^^^^^^^^^^^^^^^^^^^^^^^
  File "C:\Users\Erick\miniconda3\Lib\site-packages\wandb\sdk\lib\preinit.py", line 36, in preinit_wrapper
    raise wandb.Error(f"You must call wandb.init() before {name}()")
wandb.errors.errors.Error: You must call wandb.init() before wandb.log()
"""

The above exception was the direct cause of the following exception:

Traceback (most recent call last):
  File "c:\Users\Erick\Desktop\Project\Jupyter\DlhJupyterNotebook\train.py", line 79, in main
    joblib.Parallel(n_jobs=-1)(joblib.delayed(train_model)(name, model) for name, model in models.items())
    ~~~~~~~~~~~~~~~~~~~~~~~~~~^^^^^^^^^^^^^^^^^^^^^^^^^^^^^^^^^^^^^^^^^^^^^^^^^^^^^^^^^^^^^^^^^^^^^^^^^^^^
  File "C:\Users\Erick\miniconda3\Lib\site-packages\joblib\parallel.py", line 2007, in __call__
    return output if self.return_generator else list(output)
                                                ~~~~^^^^^^^^
  File "C:\Users\Erick\miniconda3\Lib\site-packages\joblib\parallel.py", line 1650, in _get_outputs
    yield from self._retrieve()
  File "C:\Users\Erick\miniconda3\Lib\site-packages\joblib\parallel.py", line 1754, in _retrieve
    self._raise_error_fast()
    ~~~~~~~~~~~~~~~~~~~~~~^^
  File "C:\Users\Erick\miniconda3\Lib\site-packages\joblib\parallel.py", line 1789, in _raise_error_fast
    error_job.get_result(self.timeout)
    ~~~~~~~~~~~~~~~~~~~~^^^^^^^^^^^^^^
  File "C:\Users\Erick\miniconda3\Lib\site-packages\joblib\parallel.py", line 745, in get_result
    return self._return_or_raise()
           ~~~~~~~~~~~~~~~~~~~~~^^
  File "C:\Users\Erick\miniconda3\Lib\site-packages\joblib\parallel.py", line 763, in _return_or_raise
    raise self._result
wandb.errors.errors.Error: You must call wandb.init() before wandb.log()

Set the environment variable HYDRA_FULL_ERROR=1 for a complete stack trace.
