Training model...

Starting Hyperparameter Tuning...
joblib.externals.loky.process_executor._RemoteTraceback:
"""
Traceback (most recent call last):
  File "C:\Users\Erick\miniconda3\Lib\site-packages\joblib\externals\loky\process_executor.py", line 463, in _process_worker
    r = call_item()
  File "C:\Users\Erick\miniconda3\Lib\site-packages\joblib\externals\loky\process_executor.py", line 291, in __call__
    return self.fn(*self.args, **self.kwargs)
           ~~~~~~~^^^^^^^^^^^^^^^^^^^^^^^^^^^
  File "C:\Users\Erick\miniconda3\Lib\site-packages\joblib\parallel.py", line 598, in __call__
    return [func(*args, **kwargs)
            ~~~~^^^^^^^^^^^^^^^^^
  File "C:\Users\Erick\miniconda3\Lib\site-packages\sklearn\utils\parallel.py", line 139, in __call__
    return self.function(*args, **kwargs)
           ~~~~~~~~~~~~~^^^^^^^^^^^^^^^^^
  File "C:\Users\Erick\miniconda3\Lib\site-packages\sklearn\model_selection\_validation.py", line 854, in _fit_and_score
    estimator = estimator.set_params(**clone(parameters, safe=False))
  File "C:\Users\Erick\miniconda3\Lib\site-packages\sklearn\base.py", line 283, in set_params
    raise ValueError(
    ...<2 lines>...
    )
ValueError: Invalid parameter 'Solver' for estimator LogisticRegression(C=0.01, multi_class='multinomial', random_state=42). Valid parameters are: ['C', 'class_weight', 'dual', 'fit_intercept', 'intercept_scaling', 'l1_ratio', 'max_iter', 'multi_class', 'n_jobs', 'penalty', 'random_state', 'solver', 'tol', 'verbose', 'warm_start'].
"""

The above exception was the direct cause of the following exception:

Traceback (most recent call last):
  File "c:\Users\Erick\Desktop\Project\Jupyter\DlhJupyterNotebook\train.py", line 96, in <module>
    trainer.train_model()
    ~~~~~~~~~~~~~~~~~~~^^
  File "c:\Users\Erick\Desktop\Project\Jupyter\DlhJupyterNotebook\train.py", line 54, in train_model
    self.model = self.tune_hyperparameters()
                 ~~~~~~~~~~~~~~~~~~~~~~~~~^^
  File "c:\Users\Erick\Desktop\Project\Jupyter\DlhJupyterNotebook\train.py", line 30, in tune_hyperparameters
    grid_search.fit(self.X_train, self.y_train)
    ~~~~~~~~~~~~~~~^^^^^^^^^^^^^^^^^^^^^^^^^^^^
  File "C:\Users\Erick\miniconda3\Lib\site-packages\sklearn\base.py", line 1389, in wrapper
    return fit_method(estimator, *args, **kwargs)
  File "C:\Users\Erick\miniconda3\Lib\site-packages\sklearn\model_selection\_search.py", line 1024, in fit
    self._run_search(evaluate_candidates)
    ~~~~~~~~~~~~~~~~^^^^^^^^^^^^^^^^^^^^^
  File "C:\Users\Erick\miniconda3\Lib\site-packages\sklearn\model_selection\_search.py", line 1571, in _run_search
    evaluate_candidates(ParameterGrid(self.param_grid))
    ~~~~~~~~~~~~~~~~~~~^^^^^^^^^^^^^^^^^^^^^^^^^^^^^^^^
  File "C:\Users\Erick\miniconda3\Lib\site-packages\sklearn\model_selection\_search.py", line 970, in evaluate_candidates
    out = parallel(
        delayed(_fit_and_score)(
    ...<13 lines>...
        )
    )
  File "C:\Users\Erick\miniconda3\Lib\site-packages\sklearn\utils\parallel.py", line 77, in __call__
    return super().__call__(iterable_with_config)
           ~~~~~~~~~~~~~~~~^^^^^^^^^^^^^^^^^^^^^^
  File "C:\Users\Erick\miniconda3\Lib\site-packages\joblib\parallel.py", line 2007, in __call__
    return output if self.return_generator else list(output)
                                                ~~~~^^^^^^^^
  File "C:\Users\Erick\miniconda3\Lib\site-packages\joblib\parallel.py", line 1650, in _get_outputs
    yield from self._retrieve()
  File "C:\Users\Erick\miniconda3\Lib\site-packages\joblib\parallel.py", line 1754, in _retrieve
    self._raise_error_fast()
    ~~~~~~~~~~~~~~~~~~~~~~^^
  File "C:\Users\Erick\miniconda3\Lib\site-packages\joblib\parallel.py", line 1789, in _raise_error_fast
    error_job.get_result(self.timeout)
    ~~~~~~~~~~~~~~~~~~~~^^^^^^^^^^^^^^
  File "C:\Users\Erick\miniconda3\Lib\site-packages\joblib\parallel.py", line 745, in get_result
    return self._return_or_raise()
           ~~~~~~~~~~~~~~~~~~~~~^^
  File "C:\Users\Erick\miniconda3\Lib\site-packages\joblib\parallel.py", line 763, in _return_or_raise
    raise self._result
ValueError: Invalid parameter 'Solver' for estimator LogisticRegression(C=0.01, multi_class='multinomial', random_state=42). Valid parameters are: ['C', 'class_weight', 'dual', 'fit_intercept', 'intercept_scaling', 'l1_ratio', 'max_iter', 'multi_class', 'n_jobs', 'penalty', 'random_state', 'solver', 'tol', 'verbose', 'warm_start'].
